Workbook

Sheet Summary
A1: TEST CASE SCENERIOS
A2: Covers: Order Management, Partial Order & Seller Processing, Roles & Permissions, Logistics & Delivery, Onboarding/Subscription/Commission, Pricing & Settlement, Reward Engine, Catalog/Search, Notifications & Post-Order, End-to-End Business Flows, New-Role Access (Delivery Partner/Operator/Finance), Integration, Exception/Negative, SEO, Performance/UX, Order Rescue & Reassignment, Order Restoration Management, and Dashboards & Analytics
A4: # | B4: Module / Sheet | C4: Total Test Cases | D4: High Priority | E4: Medium Priority | F4: Low Priority
A5: 1 | B5: Customer Order Mgmt | C5: ='Customer Order Mgmt'!$A$26 | D5: =COUNTIF('Customer Order Mgmt'!$J$3:$J$26,"High") | E5: =COUNTIF('Customer Order Mgmt'!$J$3:$J$26,"Medium") | F5: =COUNTIF('Customer Order Mgmt'!$J$3:$J$26,"Low")
A6: 2 | B6: Partial Order & Seller Ops | C6: ='Partial Order & Seller Ops'!$A$26 | D6: =COUNTIF('Partial Order & Seller Ops'!$J$3:$J$26,"High") | E6: =COUNTIF('Partial Order & Seller Ops'!$J$3:$J$26,"Medium") | F6: =COUNTIF('Partial Order & Seller Ops'!$J$3:$J$26,"Low")
A7: 3 | B7: Roles & Permissions | C7: ='Roles & Permissions'!$A$19 | D7: =COUNTIF('Roles & Permissions'!$J$3:$J$19,"High") | E7: =COUNTIF('Roles & Permissions'!$J$3:$J$19,"Medium") | F7: =COUNTIF('Roles & Permissions'!$J$3:$J$19,"Low")
A8: 4 | B8: Logistics & Delivery | C8: ='Logistics & Delivery'!$A$19 | D8: =COUNTIF('Logistics & Delivery'!$J$3:$J$19,"High") | E8: =COUNTIF('Logistics & Delivery'!$J$3:$J$19,"Medium") | F8: =COUNTIF('Logistics & Delivery'!$J$3:$J$19,"Low")
A9: 5 | B9: Onboarding, Subscription & Comm | C9: ='Onboarding, Subscription & Comm'!$A$17 | D9: =COUNTIF('Onboarding, Subscription & Comm'!$J$3:$J$17,"High") | E9: =COUNTIF('Onboarding, Subscription & Comm'!$J$3:$J$17,"Medium") | F9: =COUNTIF('Onboarding, Subscription & Comm'!$J$3:$J$17,"Low")
A10: 6 | B10: Pricing, Charges & Settlement | C10: ='Pricing, Charges & Settlement'!$A$16 | D10: =COUNTIF('Pricing, Charges & Settlement'!$J$3:$J$16,"High") | E10: =COUNTIF('Pricing, Charges & Settlement'!$J$3:$J$16,"Medium") | F10: =COUNTIF('Pricing, Charges & Settlement'!$J$3:$J$16,"Low")
A11: 7 | B11: Reward Engine | C11: ='Reward Engine'!$A$18 | D11: =COUNTIF('Reward Engine'!$J$3:$J$18,"High") | E11: =COUNTIF('Reward Engine'!$J$3:$J$18,"Medium") | F11: =COUNTIF('Reward Engine'!$J$3:$J$18,"Low")
A12: 8 | B12: Catalog, Search & Discovery | C12: ='Catalog, Search & Discovery'!$A$12 | D12: =COUNTIF('Catalog, Search & Discovery'!$J$3:$J$12,"High") | E12: =COUNTIF('Catalog, Search & Discovery'!$J$3:$J$12,"Medium") | F12: =COUNTIF('Catalog, Search & Discovery'!$J$3:$J$12,"Low")
A13: 9 | B13: Notifications & Post-Order | C13: ='Notifications & Post-Order'!$A$12 | D13: =COUNTIF('Notifications & Post-Order'!$J$3:$J$12,"High") | E13: =COUNTIF('Notifications & Post-Order'!$J$3:$J$12,"Medium") | F13: =COUNTIF('Notifications & Post-Order'!$J$3:$J$12,"Low")
A14: 10 | B14: E2E Business Flow | C14: ='E2E Business Flow'!$A$15 | D14: =COUNTIF('E2E Business Flow'!$J$3:$J$15,"High") | E14: =COUNTIF('E2E Business Flow'!$J$3:$J$15,"Medium") | F14: =COUNTIF('E2E Business Flow'!$J$3:$J$15,"Low")
A15: 11 | B15: Role-wise Testing (New Roles) | C15: ='Role-wise Testing (New Roles)'!$A$13 | D15: =COUNTIF('Role-wise Testing (New Roles)'!$J$3:$J$13,"High") | E15: =COUNTIF('Role-wise Testing (New Roles)'!$J$3:$J$13,"Medium") | F15: =COUNTIF('Role-wise Testing (New Roles)'!$J$3:$J$13,"Low")
A16: 12 | B16: Integration Testing | C16: ='Integration Testing'!$A$14 | D16: =COUNTIF('Integration Testing'!$J$3:$J$14,"High") | E16: =COUNTIF('Integration Testing'!$J$3:$J$14,"Medium") | F16: =COUNTIF('Integration Testing'!$J$3:$J$14,"Low")
A17: 13 | B17: Exception & Negative Testing | C17: ='Exception & Negative Testing'!$A$16 | D17: =COUNTIF('Exception & Negative Testing'!$J$3:$J$16,"High") | E17: =COUNTIF('Exception & Negative Testing'!$J$3:$J$16,"Medium") | F17: =COUNTIF('Exception & Negative Testing'!$J$3:$J$16,"Low")
A18: 14 | B18: SEO & Discoverability | C18: ='SEO & Discoverability'!$A$13 | D18: =COUNTIF('SEO & Discoverability'!$J$3:$J$13,"High") | E18: =COUNTIF('SEO & Discoverability'!$J$3:$J$13,"Medium") | F18: =COUNTIF('SEO & Discoverability'!$J$3:$J$13,"Low")
A19: 15 | B19: Performance & UX | C19: ='Performance & UX'!$A$10 | D19: =COUNTIF('Performance & UX'!$J$3:$J$10,"High") | E19: =COUNTIF('Performance & UX'!$J$3:$J$10,"Medium") | F19: =COUNTIF('Performance & UX'!$J$3:$J$10,"Low")
A20: 16 | B20: Order Rescue & Reassignment | C20: ='Order Rescue & Reassignment'!$A$20 | D20: =COUNTIF('Order Rescue & Reassignment'!$J$3:$J$20,"High") | E20: =COUNTIF('Order Rescue & Reassignment'!$J$3:$J$20,"Medium") | F20: =COUNTIF('Order Rescue & Reassignment'!$J$3:$J$20,"Low")
A21: 17 | B21: Order Restoration Mgmt | C21: ='Order Restoration Mgmt'!$A$19 | D21: =COUNTIF('Order Restoration Mgmt'!$J$3:$J$19,"High") | E21: =COUNTIF('Order Restoration Mgmt'!$J$3:$J$19,"Medium") | F21: =COUNTIF('Order Restoration Mgmt'!$J$3:$J$19,"Low")
A22: 18 | B22: Dashboards & Analytics | C22: ='Dashboards & Analytics'!$A$17 | D22: =COUNTIF('Dashboards & Analytics'!$J$3:$J$17,"High") | E22: =COUNTIF('Dashboards & Analytics'!$J$3:$J$17,"Medium") | F22: =COUNTIF('Dashboards & Analytics'!$J$3:$J$17,"Low")
A23: 19 | B23: extras | C23: 100 | D23: 79 | E23: 21 | F23: 0
B24: TOTAL | C24: =SUM(C5:C23) | D24: =SUM(D5:D23) | E24: =SUM(E5:E23) | F24: =SUM(F5:F23)
A26: Production Readiness — Additional Sheets
A27: Sheet | B27: Total Items | C27: Completed / Implemented | D27: Pending
A28: UAT Requirement Matrix | B28: =COUNTA('UAT Requirement Matrix'!$A$3:$A$23) | C28: =COUNTIF('UAT Requirement Matrix'!$F$3:$F$23,"Implemented") | D28: =COUNTIF('UAT Requirement Matrix'!$F$3:$F$23,"Pending Verification")
A29: Go-Live Sign-off Checklist | B29: =COUNTA('Go-Live Sign-off Checklist'!$A$3:$A$19) | C29: =COUNTIF('Go-Live Sign-off Checklist'!$D$3:$D$19,"Pass") | D29: =COUNTIF('Go-Live Sign-off Checklist'!$D$3:$D$19,"Pending")
A31: Legend
A32: • Priority: High = core business rule / revenue-or-compliance impact | Medium = important flow | Low = convenience feature
A33: • Type: Positive = expected/happy path | Negative = should be blocked/rejected | Edge = boundary or unusual condition
A34: • Status column supports dropdown: Not Executed / Pass / Fail / Blocked — update while executing test cycles
A35: • Test Case ID format: TC-<MODULE PREFIX>-<sequence> e.g. TC-ORD-001
A36: • New sheets added for Go-Live readiness: E2E Business Flow, Role-wise Testing (New Roles), Integration Testing, Exception & Negative Testing, SEO & Discoverability, Performance & UX, UAT Requirement Matrix, and Go-Live Sign-off Checklist.

Sheet Extras
A1: Extras — Test Case Scenarios
A2: S.No | B2: Test Case ID | C2: Module | D2: Sub-Feature / Flow | E2: Test Scenario | F2: Preconditions | G2: Test Steps | H2: Test Data | I2: Expected Result | J2: Priority | K2: Type | L2: Actor / Role | M2: Status
A3: 1 | B3: TC-USER-001 | C3: User | D3: Registration | E3: Register with valid details | F3: Registration page open | G3: Enter valid details → Submit | H3: Name, mobile, email, password | I3: Account should be created successfully | J3: High | K3: Functional | L3: User | M3: PASS
A4: 2 | B4: TC-USER-002 | C4: User | D4: Registration | E4: Register with existing mobile/email | F4: Account already exists | G4: Enter registered details → Submit | H4: Existing email/mobile | I4: Proper validation message should appear | J4: High | K4: Negative | L4: User | M4: PASS
A5: 3 | B5: TC-USER-003 | C5: User | D5: Login | E5: Login with valid credentials | F5: User registered | G5: Enter credentials → Login | H5: Valid credentials | I5: User should log in successfully | J5: High | K5: Functional | L5: User | M5: PASS
A6: 4 | B6: TC-USER-004 | C6: User | D6: Login | E6: Login with incorrect otp | F6: User registered | G6: Enter wrong otp → Login | H6: Invalid otp | I6: Login should fail | J6: High | K6: Negative | L6: User | M6: PASS
A7: 5 | B7: TC-USER-005 | C7: User | D7: Forgot Password | E7: Reset password | F7: User account exists | G7: Click Forgot Password → Verify OTP → Reset | H7: Valid OTP/new password | I7: Password should be reset successfully | J7: High | K7: Functional | L7: User | M7: FAIL | N7: removed password
A8: 6 | B8: TC-USER-006 | C8: User | D8: Profile | E8: Update profile | F8: User logged in | G8: Edit profile → Save | H8: Valid profile details | I8: Profile should be updated | J8: Medium | K8: Functional | L8: User | M8: PASS
A9: 7 | B9: TC-USER-007 | C9: User | D9: Address | E9: Add delivery address | F9: User logged in | G9: Add address → Save | H9: Valid address | I9: Address should be saved | J9: High | K9: Functional | L9: User | M9: PASS
A10: 8 | B10: TC-USER-008 | C10: User | D10: Address | E10: Edit saved address | F10: Address exists | G10: Edit address → Save | H10: Updated address | I10: Address should be updated | J10: Medium | K10: Functional | L10: User | M10: PASS
A11: 9 | B11: TC-USER-009 | C11: User | D11: Address | E11: Delete address | F11: Address exists | G11: Select address → Delete | H11: Existing address | I11: Address should be deleted | J11: Medium | K11: Functional | L11: User | M11: PASS
A12: 10 | B12: TC-USER-010 | C12: User | D12: Address | E12: Set default address | F12: Multiple addresses exist | G12: Select address → Set Default | H12: Saved address | I12: Selected address becomes default | J12: Medium | K12: Functional | L12: User | M12: PASS
A13: 11 | B13: TC-USER-011 | C13: User | D13: Product Search | E13: Search product by name | F13: Products exist | G13: Enter product name → Search | H13: "Shoes" | I13: Relevant products should appear | J13: High | K13: Functional | L13: User | M13: PASS
A14: 12 | B14: TC-USER-012 | C14: User | D14: Search | E14: Search with invalid keyword | F14: User logged in | G14: Search random keyword | H14: "XYZ123" | I14: No-result message should appear | J14: Medium | K14: Negative | L14: User | M14: PASS
A15: 13 | B15: TC-USER-013 | C15: User | D15: Category | E15: Browse products by category | F15: Categories exist | G15: Select category | H15: Electronics | I15: Correct products should appear | J15: High | K15: Functional | L15: User | M15: PASS
A16: 14 | B16: TC-USER-014 | C16: User | D16: Filter | E16: Filter by price | F16: Products exist | G16: Apply price filter | H16: ₹500–₹1,000 | I16: Only products within range should appear | J16: Medium | K16: Functional | L16: User | M16: FAIL
A17: 15 | B17: TC-USER-015 | C17: User | D17: Filter | E17: Filter by brand | F17: Multiple brands exist | G17: Select brand | H17: Nike | I17: Selected brand products displayed | J17: Medium | K17: Functional | L17: User | M17: FAIL
A18: 16 | B18: TC-USER-016 | C18: User | D18: Sort | E18: Sort products by price | F18: Products displayed | G18: Select Low to High | H18: Price | I18: Products sorted correctly | J18: Medium | K18: Functional | L18: User | M18: PASS
A19: 17 | B19: TC-USER-017 | C19: User | D19: Product Details | E19: View product details | F19: Product exists | G19: Open product | H19: Product ID | I19: Correct image, name, price, description and specifications displayed | J19: High | K19: Functional | L19: User | M19: PASS
... A102: 100 | B102: TC-E2E-100 | C102: Security | D102: Role Access | E102: Verify unauthorized panel access | F102: Multiple roles exist | G102: Attempt accessing another role's functions | H102: User/Seller/Admin accounts | I102: Unauthorized functions should be inaccessible | J102: High | K102: Security | L102: All Roles | M102: PASS

Sheet Customer Order Mgmt
A1: Customer Order Management — Test Case Scenarios
A2: S.No | B2: Test Case ID | C2: Module | D2: Sub-Feature / Flow | E2: Test Scenario | F2: Preconditions | G2: Test Steps | H2: Test Data | I2: Expected Result | J2: Priority | K2: Type | L2: Actor / Role | M2: Status
A3: 1 | B3: TC-ORD-001 | C3: Customer Order Management | D3: Regular Order | E3: Place a regular order successfully | F3: Customer logged in; shop is open; products in stock | G3: 1. Browse shop and add products to cart 2. Select delivery date = Today 3. Proceed to checkout and complete payment | H3: Valid product SKUs, valid UPI/card payment method | I3: Order placed successfully; status = 'Order Placed'; seller receives order notification; order visible in customer order history | J3: High | K3: Positive | L3: Customer | M3: PASS
A4: 2 | B4: TC-ORD-002 | C4: Customer Order Management | D4: Regular Order | E4: Attempt to add an out-of-stock product to cart | F4: Product stock = 0 | G4: 1. Search/browse for the out-of-stock product 2. Attempt to add to cart | H4: Product with stock quantity 0 | I4: Product is not displayed / not addable in customer app, per 'out-of-stock products hidden' rule | J4: High | K4: Negative | L4: Customer | M4: PASS
A5: 3 | B5: TC-ORD-003 | C5: Customer Order Management | D5: Regular Order | E5: Attempt to place order after 10 PM cut-off | F5: Current time is after 10:00 PM; platform order-timing restriction active | G5: 1. Add items to cart 2. Attempt checkout at 10:05 PM | H5: System clock/time = 22:05 | I5: Order placement is blocked; customer sees a message about the timing restriction (or order is auto-scheduled per odd-hour config) | J5: High | K5: Negative | L5: Customer | M5: PASS
A6: 4 | B6: TC-ORD-004 | C6: Customer Order Management | D6: Scheduled Order | E6: Place a scheduled order for a future date | F6: Seller supports scheduled orders; delivery calendar available | G6: 1. Add products to cart 2. Select a future delivery date from calendar 3. Complete payment | H6: Future date within seller's allowed scheduling range | I6: Order created with status 'Scheduled'; delivery date stored correctly; seller notified as a scheduled order | J6: High | K6: Positive | L6: Customer | M6: PASS
A7: 5 | B7: TC-ORD-005 | C7: Customer Order Management | D7: Scheduled Order | E7: Reschedule a scheduled order before seller's cut-off time | F7: Order is in 'Scheduled' state; current time before seller-defined cut-off | G7: 1. Open order 2. Select 'Reschedule' 3. Choose a new valid future date 4. Confirm | H7: New delivery date within valid window | I7: Order rescheduled successfully; customer receives confirmation message with new date | J7: Medium | K7: Positive | L7: Customer | M7: PASS
A8: 6 | B8: TC-ORD-006 | C8: Customer Order Management | D8: Scheduled Order | E8: Attempt to reschedule after cut-off time has passed | F8: Current time is past seller-defined cut-off for that scheduled order | G8: 1. Open scheduled order 2. Attempt to reschedule | H8: Cut-off time already elapsed | I8: Reschedule option disabled/blocked; system shows cut-off-passed message | J8: Medium | K8: Negative | L8: Customer | M8: PASS
A9: 7 | B9: TC-ORD-007 | C9: Customer Order Management | D9: Pre-Order | E9: Place a pre-order within an active campaign window | F9: Seller has published a pre-order campaign with a defined sale/delivery window | G9: 1. Browse pre-order section 2. Add pre-order product to cart 3. Select delivery date within campaign window 4. Complete payment | H9: Delivery date inside campaign window | I9: Order confirmed; awaits campaign sale-start date; delivery scheduled within campaign window only | J9: High | K9: Positive | L9: Customer | M9: PASS
A10: 8 | B10: TC-ORD-008 | C10: Customer Order Management | D10: Pre-Order | E10: Attempt to book a pre-order beyond the 1-month advance booking limit | F10: Pre-order product configured; advance booking capped at 1 month | G10: 1. Select pre-order product 2. Attempt to choose a delivery date more than 30 days out | H10: Delivery date = today + 45 days | I10: Date selection blocked/unavailable; system restricts to max 1-month advance window | J10: High | K10: Negative | L10: Customer | M10: PASS
A11: 9 | B11: TC-ORD-009 | C11: Customer Order Management | D11: Mixed Cart Order | E11: Cart with regular + pre-order item auto-aligns to future date | F11: Cart contains one regular (immediate) item and one pre-order item with a future date | G11: 1. Add a regular item to cart 2. Add a pre-order item to same cart 3. Proceed to cart/checkout | H11: Regular item (immediate) + Pre-order item (future date T+10) | I11: Cart page behaves as scheduling page; entire order aligned to the pre-order item's future delivery date; only valid dates for that item are selectable | J11: High | K11: Edge | L11: Customer | M11: PASS
A12: 10 | B12: TC-ORD-010 | C12: Customer Order Management | D12: Mixed Cart Order | E12: Cart with two pre-order items having different delivery windows | F12: Two different pre-order campaigns with non-overlapping delivery windows | G12: 1. Add pre-order item A (window: 5-10 Aug) 2. Add pre-order item B (window: 15-20 Aug) to same cart | H12: Item A + Item B, conflicting windows | I12: System detects conflicting scheduling windows and either blocks combined checkout or prompts to split into separate orders | J12: Medium | K12: Edge | L12: Customer | M12: PASS
A13: 11 | B13: TC-ORD-011 | C13: Customer Order Management | D13: Cart Modification | E13: Modify cart (add/remove items) before seller acceptance | F13: Order placed but not yet accepted by seller | G13: 1. Open order 2. Add an extra item / remove an item 3. Save changes | H13: Order in 'Placed'/'Seller Review' state | I13: Cart update succeeds; order total recalculated automatically | J13: High | K13: Positive | L13: Customer | M13: PASS
A14: 12 | B14: TC-ORD-012 | C14: Customer Order Management | D14: Cart Modification | E14: Attempt direct cart edit after seller acceptance | F14: Order already accepted by seller | G14: 1. Open accepted order 2. Attempt to add/remove item directly | H14: Order in 'Accepted' state | I14: Direct edit is disabled; customer is redirected to raise a modification/reschedule request instead | J14: High | K14: Negative | L14: Customer | M14: PASS
... A26: 24 | B26: TC-ORD-024 | C26: Customer Order Management | D26: Wallet & Revised Bill | E26: Wallet balance insufficient to cover a price-revised bill | F26: Seller has issued a revised (higher) bill after replacement/price increase; customer wallet balance < difference | G26: 1. Seller revises bill upward 2. Customer notified to pay difference 3. Customer attempts payment with insufficient wallet balance | H26: Wallet balance = ₹50; amount due = ₹120 | I26: System prompts alternate payment method (UPI/card) for the shortfall; order remains 'Awaiting Additional Payment' until resolved | J26: High | K26: Edge | L26: Customer | M26: PASS

Sheet Partial Order & Seller Ops
A1: Partial Order & Seller Processing — Test Case Scenarios
A2: S.No | B2: Test Case ID | C2: Module | D2: Sub-Feature / Flow | E2: Test Scenario | F2: Preconditions | G2: Test Steps | H2: Test Data | I2: Expected Result | J2: Priority | K2: Type | L2: Actor / Role | M2: Status
A3: 1 | B3: TC-PART-001 | C3: Partial Order & Seller Processing | D3: Inventory Review | E3: Seller reviews inventory - all items available - accepts order | F3: New order received by seller | G3: 1. Seller opens new order 2. Checks product availability 3. Taps 'Accept Order' | H3: All items in stock | I3: Order accepted; status moves to 'Preparing'; customer notified | J3: High | K3: Positive | L3: Seller | M3: PASS
A4: 2 | B4: TC-PART-002 | C4: Partial Order & Seller Processing | D4: Inventory Review | E4: Seller reviews inventory - some items unavailable - triggers partial-order decision | F4: New order received; one or more items out of stock | G4: 1. Seller opens order 2. Checks availability 3. System flags unavailable item(s) | H4: Order with 4 items, 1 unavailable | I4: Seller is routed to Partial Order Decision screen (Cancel / Split / Replace / Reject options) | J4: High | K4: Positive | L4: Seller | M4: FAIL
A5: 3 | B5: TC-PART-003 | C5: Partial Order & Seller Processing | D5: Partial Cancellation | E5: Seller partially cancels unavailable item and continues remaining order | F5: Order flagged with unavailable item(s) | G5: 1. Select 'Partial Cancellation' 2. Choose unavailable item(s) 3. Confirm cancellation of selected items only | H5: 1 of 4 items unavailable | I5: Selected item cancelled; wallet refund auto-generated for that item; settlement recalculated; remaining order proceeds | J5: High | K5: Positive | L5: Seller | M5: FAIL
A6: 4 | B6: TC-PART-004 | C6: Partial Order & Seller Processing | D6: Split Delivery | E6: Split delivery - available items today, remainder scheduled next day | F6: Order has both available and unavailable-until-tomorrow items | G6: 1. Select 'Split Delivery' 2. Confirm items for today 3. Schedule remaining items for next delivery 4. Send for customer confirmation | H6: 2 items available now, 2 arriving tomorrow | I6: Two separate delivery records created; customer notified and must confirm before dispatch | J6: High | K6: Positive | L6: Seller | M6: PASS
A7: 5 | B7: TC-PART-005 | C7: Partial Order & Seller Processing | D7: Split Delivery | E7: Additional logistics charge applied and requires customer confirmation | F7: Split delivery selected; extra delivery run needed | G7: 1. Seller applies additional delivery charge for second trip 2. Sends revised bill to customer | H7: Extra delivery fee = ₹25 | I7: Customer sees revised bill with added charge and must confirm before split order proceeds | J7: Medium | K7: Positive | L7: Seller | M7: PASS
A8: 6 | B8: TC-PART-006 | C8: Partial Order & Seller Processing | D8: Split Delivery | E8: Customer rejects the additional split-delivery charge | F8: Revised bill with extra logistics charge sent to customer | G8: 1. Customer opens revised bill 2. Taps 'Reject' | H8: Extra delivery fee proposed | I8: Split delivery is not confirmed; seller must offer an alternative (e.g., cancel unavailable item, full split at no charge if configured) | J8: Medium | K8: Negative | L8: Seller | M8: PASS
A9: 7 | B9: TC-PART-007 | C9: Partial Order & Seller Processing | D9: Product Replacement | E9: Seller suggests replacement and customer approves | F9: Item unavailable; alternative in stock | G9: 1. Seller selects 'Product Replacement' 2. Suggests alternate product 3. Sends to customer for approval 4. Customer approves | H9: Original ₹250 item replaced with ₹250 alternative | I9: Order continues with replacement item; invoice updated; no price impact (equal price) | J9: High | K9: Positive | L9: Seller | M9: PASS
A10: 8 | B10: TC-PART-008 | C10: Partial Order & Seller Processing | D10: Product Replacement | E10: Customer rejects replacement - partial refund issued | F10: Replacement suggested but rejected by customer | G10: 1. Customer reviews replacement 2. Taps 'Reject' | H10: Unavailable item value = ₹250 | I10: Unavailable item cancelled; ₹250 refunded to wallet; order continues with remaining items | J10: High | K10: Positive | L10: Seller | M10: PASS
A11: 9 | B11: TC-PART-009 | C11: Partial Order & Seller Processing | D11: Reject Order | E11: Reject complete order - entire inventory unavailable | F11: All items in the order are unavailable / seller cannot fulfill | G11: 1. Seller selects 'Reject Complete Order' 2. Confirms rejection with reason | H11: Entire cart unavailable | I11: Full refund issued to customer wallet; order status = 'Closed'; customer notified with reason | J11: High | K11: Positive | L11: Seller | M11: PASS
A12: 10 | B12: TC-PART-010 | C12: Partial Order & Seller Processing | D12: Revised Invoice | E12: Revised invoice generated correctly after partial cancellation | F12: Partial cancellation processed | G12: 1. Complete partial cancellation flow 2. Open generated invoice | H12: Original order ₹1,245; 1 item (₹60) cancelled | I12: Revised invoice reflects new total (₹1,185) with itemized breakup and cancellation note | J12: High | K12: Positive | L12: Seller | M12: PASS
A13: 11 | B13: TC-PART-011 | C13: Partial Order & Seller Processing | D13: Price Adjustment | E13: Replacement item priced higher - customer pays difference | F13: Replacement item costs more than original | G13: 1. Seller suggests higher-priced replacement 2. Customer approves 3. System calculates price difference | H13: Original ₹100 -> Replacement ₹130 | I13: Customer prompted to pay ₹30 difference via wallet/UPI/card before order proceeds | J13: High | K13: Positive | L13: Seller | M13: PASS
A14: 12 | B14: TC-PART-012 | C14: Partial Order & Seller Processing | D14: Price Adjustment | E14: Replacement item priced lower - refund credited to wallet | F14: Replacement item costs less than original | G14: 1. Seller suggests lower-priced replacement 2. Customer approves | H14: Original ₹150 -> Replacement ₹120 | I14: ₹30 automatically credited to customer wallet; settlement updated | J14: High | K14: Positive | L14: Seller | M14: PASS
... A26: 24 | B26: TC-PART-024 | C26: Partial Order & Seller Processing | D26: Dispute Resolution | E26: Super Admin resolves a customer dispute | F26: Open complaint/dispute linked to an order | G26: 1. Super Admin reviews complaint details 2. Coordinates with seller/customer 3. Records resolution | H26: Dispute over damaged/missing item | I26: Dispute marked resolved with outcome (refund/replacement/rejection) and reason logged | J26: Medium | K26: Positive | L26: Super Admin | M26: PASS

Sheet Roles & Permissions
A1: Roles & Permissions — Test Case Scenarios
A2: S.No | B2: Test Case ID | C2: Module | D2: Sub-Feature / Flow | E2: Test Scenario | F2: Preconditions | G2: Test Steps | H2: Test Data | I2: Expected Result | J2: Priority | K2: Type | L2: Actor / Role | M2: Status
A3: 1 | B3: TC-ROLE-001 | C3: Roles & Permissions | D3: Customer Permissions | E3: Customer modifies order freely before seller acceptance | F3: Order not yet accepted | G3: 1. Customer opens order 2. Adds/removes items, changes quantity, or cancels | H3: Order in 'Placed' state | I3: All modification actions succeed without seller intervention | J3: High | K3: Positive | L3: Customer | M3: PASS
A4: 2 | B4: TC-ROLE-002 | C4: Roles & Permissions | D4: Customer Permissions | E4: Customer attempts direct edit after seller acceptance | F4: Order accepted | G4: 1. Customer attempts to directly modify accepted order | H4: Order in 'Accepted' state | I4: Direct edit disabled; only 'Raise Request' options (Modify/Reschedule/Partial Cancel) available | J4: High | K4: Negative | L4: Customer | M4: PASS
A5: 3 | B5: TC-ROLE-003 | C5: Roles & Permissions | D5: Seller (Admin) Access | E5: Seller (Shop Admin) has full access to shop settings and finance | F5: Seller logged into Seller Hub | G5: 1. Navigate through Dashboard, Orders, Products, Finance, Subscription, Assistants, Settings | H5: Seller/Admin account | I5: Full access granted to all modules including Finance & Payouts, Subscription, and Assistant management | J5: Medium | K5: Positive | L5: Seller | M5: PASS
A6: 4 | B6: TC-ROLE-004 | C6: Roles & Permissions | D6: Assistant Creation | E6: Seller creates an assistant and assigns shop-wise permission | F6: Seller account with at least one shop | G6: 1. Seller opens 'Assistants' 2. Adds new assistant 3. Assigns to specific shop(s) 4. Sets role/permission level | H6: New assistant, assigned to Shop 1 only, Operational role | I6: Assistant account created with restricted access limited to Shop 1 and Operational-level actions | J6: High | K6: Positive | L6: Seller | M6: PASS
A7: 5 | B7: TC-ROLE-005 | C7: Roles & Permissions | D7: Assistant - View Only | E7: Assistant with View-Only permission attempts to modify an order | F7: Assistant assigned View-Only role | G7: 1. Assistant logs in 2. Opens order 3. Attempts to accept/modify | H7: View-Only role | I7: Action blocked; assistant can only view data, not perform operations | J7: High | K7: Negative | L7: Assistant | M7: PASS
A8: 6 | B8: TC-ROLE-006 | C8: Roles & Permissions | D8: Assistant - Operational | E8: Assistant with Operational permission accepts and modifies an order | F8: Assistant assigned Operational role | G8: 1. Assistant logs in 2. Accepts order, updates stock, modifies orders | H8: Operational role | I8: Actions succeed for allowed categories (orders/inventory); finance-related actions remain blocked | J8: Medium | K8: Positive | L8: Assistant | M8: PASS
A9: 7 | B9: TC-ROLE-007 | C9: Roles & Permissions | D9: Assistant - Full Operation | E9: Assistant with Full Operation permission performs all order actions except finance | F9: Assistant assigned Full Operation role | G9: 1. Assistant performs accept/reject, split delivery, replace product, reschedule 2. Attempts finance action | H9: Full Operation role | I9: All operational actions succeed; finance/settlement/subscription actions remain blocked | J9: Medium | K9: Positive | L9: Assistant | M9: PASS
A10: 8 | B10: TC-ROLE-008 | C10: Roles & Permissions | D10: Assistant Restrictions | E10: Assistant (any level) attempts to access Finance & Payouts | F10: Assistant of any permission level | G10: 1. Assistant navigates to Finance & Payouts section | H10: Any assistant role | I10: Access denied - 'No Access (Restricted)' regardless of assigned permission level | J10: High | K10: Negative | L10: Assistant | M10: FAIL
A11: 9 | B11: TC-ROLE-009 | C11: Roles & Permissions | D11: Assistant Restrictions | E11: Assistant attempts to add/remove another assistant | F11: Assistant of any permission level | G11: 1. Assistant opens 'Assistants' module 2. Attempts to add/remove an assistant | H11: Any assistant role | I11: Action blocked; only Seller (Admin) can manage assistants | J11: High | K11: Negative | L11: Assistant | M11: PASS
A12: 10 | B12: TC-ROLE-010 | C12: Roles & Permissions | D12: Assistant Restrictions | E12: Assistant attempts to change their own role/permission | F12: Assistant logged in | G12: 1. Assistant navigates to their own profile/permission settings 2. Attempts to change role | H12: Any assistant role | I12: Action blocked; only Seller can set/change assistant roles and permissions | J12: High | K12: Negative | L12: Assistant | M12: PASS
A13: 11 | B13: TC-ROLE-011 | C13: Roles & Permissions | D13: Access Revocation | E13: Seller disables an assistant's access | F13: Active assistant with granted permissions | G13: 1. Seller opens Assistants list 2. Toggles 'Disable Access' for an assistant | H13: Active assistant | I13: Assistant immediately loses access on next action/login attempt; seller can re-enable anytime | J13: Medium | K13: Positive | L13: Seller | M13: PASS
A14: 12 | B14: TC-ROLE-012 | C14: Roles & Permissions | D14: Super Admin Oversight | E14: Super Admin views complete audit logs across all sellers | F14: Super Admin logged in | G14: 1. Navigate to Audit Logs 2. Filter by seller/date/action type | H14: Multiple sellers with transaction history | I14: Complete, filterable audit trail displayed across all sellers and shops | J14: Medium | K14: Positive | L14: Super Admin | M14: FAIL
... A19: 17 | B19: TC-ROLE-017 | C19: Roles & Permissions | D19: Multi-Assistant Isolation | E19: Multiple assistants assigned to different shops maintain isolated access | F19: Seller has 2+ shops, each with a different assistant assigned | G19: 1. Assistant A (Shop 1) logs in 2. Attempts to view/act on Shop 2 orders | H19: Assistant A assigned only to Shop 1 | I19: Assistant A cannot view or act on Shop 2 data; strict shop-wise data isolation enforced | J19: High | K19: Edge | L19: Assistant | M19: PASS

Sheet Onboarding, Subscription & Comm
A1: Seller Onboarding, Subscription & Commission — Test Case Scenarios
A2: S.No | B2: Test Case ID | C2: Module | D2: Sub-Feature / Flow | E2: Test Scenario | F2: Preconditions | G2: Test Steps | H2: Test Data | I2: Expected Result | J2: Priority | K2: Type | L2: Actor / Role | M2: Status
A3: 1 | B3: TC-SUB-001 | C3: Seller Onboarding, Subscription & Commission | D3: Onboarding | E3: Seller registers and submits KYC documents | F3: New user registered as customer/user | G3: 1. User taps 'Become a Seller' 2. Fills business details 3. Uploads PAN/GST/Bank documents 4. Submits application | H3: Valid PAN, GST, bank details | I3: Application submitted with status 'KYC Pending' | J3: High | K3: Positive | L3: Seller | M3: PASS
A4: 2 | B4: TC-SUB-002 | C4: Seller Onboarding, Subscription & Commission | D4: Onboarding | E4: Admin verifies and approves seller KYC | F4: Seller has submitted KYC documents | G4: 1. Admin opens pending KYC queue 2. Reviews documents 3. Approves | H4: Complete and valid documents | I4: Seller status changes to 'Approved'; seller can proceed to subscribe/create shop | J4: High | K4: Positive | L4: Admin | M4: PASS
A5: 3 | B5: TC-SUB-003 | C5: Seller Onboarding, Subscription & Commission | D5: Onboarding | E5: Admin rejects seller KYC with reason | F5: Seller has submitted KYC documents with issues | G5: 1. Admin reviews documents 2. Rejects with a reason (e.g., mismatched GST) | H5: Invalid/incomplete GST document | I5: Seller notified of rejection with reason; can resubmit corrected documents | J5: Medium | K5: Negative | L5: Admin | M5: PASS
A6: 4 | B6: TC-SUB-004 | C6: Seller Onboarding, Subscription & Commission | D6: Subscription Model | E6: Seller chooses Subscription Model and selects a plan | F6: Seller approved and reached 'Choose Business Model' step | G6: 1. Seller selects 'Subscription Model' 2. Chooses shop count, product limit, duration 3. Proceeds to payment | H6: Premium Monthly plan: 3 shops, 100 products/shop, 1 month, ₹1,499 | I6: Plan selected and moved to payment step with correct amount displayed | J6: High | K6: Positive | L6: Seller | M6: PASS
A7: 5 | B7: TC-SUB-005 | C7: Seller Onboarding, Subscription & Commission | D7: Subscription Model | E7: Seller completes payment - instant activation | F7: Plan selected, payment initiated | G7: 1. Seller completes payment via UPI/card/wallet | H7: Payment amount = ₹1,499 | I7: Subscription activated instantly; shops/products enabled up to purchased limits; seller can start receiving orders | J7: High | K7: Positive | L7: Seller | M7: PASS
A8: 6 | B8: TC-SUB-006 | C8: Seller Onboarding, Subscription & Commission | D8: Subscription Expiry | E8: Subscription expires - shops/products auto-hidden | F8: Active subscription reaches its end date without renewal | G8: 1. Let subscription expiry date pass without renewal 2. Check shop/product visibility on customer app | H8: Subscription end date = today | I8: Shops and products automatically hidden from customer app; no new orders accepted; existing orders still fulfillable | J8: High | K8: Negative | L8: System | M8: PASS
A9: 7 | B9: TC-SUB-007 | C9: Seller Onboarding, Subscription & Commission | D9: Subscription Renewal | E9: Seller renews an expired subscription | F9: Subscription expired; shops hidden | G9: 1. Seller opens Subscription module 2. Renews or upgrades plan 3. Completes payment | H9: Renewal of expired Premium Monthly plan | I9: Shops and products become visible again instantly; orders can resume | J9: High | K9: Positive | L9: Seller | M9: PASS
A10: 8 | B10: TC-SUB-008 | C10: Seller Onboarding, Subscription & Commission | D10: Commission Model | E10: Seller exceeds 30-product limit without subscription | F10: Seller on base (non-subscribed) model with 30 products already listed | G10: 1. Seller attempts to add the 31st product without an active subscription | H10: 30 existing products, no subscription | I10: Seller is prompted to subscribe, OR higher commission rate is automatically applied to continue selling beyond the limit | J10: High | K10: Edge | L10: Seller | M10: PASS
A11: 9 | B11: TC-SUB-009 | C11: Seller Onboarding, Subscription & Commission | D11: Commission Model | E11: Seller opts for Commission Model instead of Subscription | F11: Seller approved and reached 'Choose Business Model' step | G11: 1. Seller selects 'Commission Model' 2. Sets selling price (commission auto-included) 3. Starts selling with no upfront fee | H11: Input price ₹100, commission 10% -> Customer price ₹120 | I11: Seller can start listing/selling immediately with no upfront payment; commission deducted at settlement | J11: High | K11: Positive | L11: Seller | M11: PASS
A12: 10 | B12: TC-SUB-010 | C12: Seller Onboarding, Subscription & Commission | D12: Commission Calculation | E12: Commission is calculated correctly at category/shop/product level | F12: Multiple commission rules configured (e.g., 10% Electronics, 5% Grocery) | G12: 1. Place orders across different categories 2. Check calculated commission per order | H12: Electronics order ₹1,000 (10%); Grocery order ₹500 (5%) | I12: Commission of ₹100 applied to Electronics order and ₹25 to Grocery order respectively | J12: High | K12: Positive | L12: System | M12: PASS
A13: 11 | B13: TC-SUB-011 | C13: Seller Onboarding, Subscription & Commission | D13: Plan Management | E13: Seller upgrades subscription plan to increase shop/product capacity | F13: Active subscription nearing shop/product limit | G13: 1. Seller opens Subscription 2. Selects 'Upgrade Plan' 3. Chooses higher tier 4. Pays difference | H13: Basic Monthly (1 shop) -> Premium Monthly (3 shops) | I13: Plan upgraded; new shop/product limits immediately available | J13: Medium | K13: Positive | L13: Seller | M13: FAIL
A14: 12 | B14: TC-SUB-012 | C14: Seller Onboarding, Subscription & Commission | D14: Shop Limit | E14: Seller adds multiple shops within subscribed limit | F14: Active subscription allows up to 3 shops; seller currently has 1 | G14: 1. Seller creates Shop 2 2. Creates Shop 3 | H14: Plan limit = 3 shops | I14: Both additional shops created successfully, each independently configurable | J14: Medium | K14: Positive | L14: Seller | M14: PASS
... A17: 15 | B17: TC-SUB-015 | C17: Seller Onboarding, Subscription & Commission | D17: Seller Referral | E17: New seller is rewarded after KYC approval and subscription purchase | F17: Existing seller refers a new seller via referral link/code | G17: 1. New seller registers using referral code 2. Completes KYC 3. Purchases a subscription | H17: Valid, non-duplicate referral code | I17: Referral reward credited to referring seller once both KYC approval and subscription purchase are complete | J17: Medium | K17: Positive | L17: System | M17: PASS

Sheet Pricing, Charges & Settlement
A1: Pricing, Charges, Invoice & Settlement — Test Case Scenarios
A2: S.No | B2: Test Case ID | C2: Module | D2: Sub-Feature / Flow | E2: Test Scenario | F2: Preconditions | G2: Test Steps | H2: Test Data | I2: Expected Result | J2: Priority | K2: Type | L2: Actor / Role | M2: Status
A3: 1 | B3: TC-PRC-001 | C3: Pricing, Charges, Invoice & Settlement | D3: Invoice Breakup | E3: Invoice generated with correct component breakup | F3: Order completed with product cost, GST, delivery fee, handling fee applicable | G3: 1. Place and complete an order 2. Open generated invoice | H3: Product ₹1,050; GST ₹0 (exempt); Delivery ₹40; Handling ₹15 | I3: Invoice shows itemized breakup summing correctly to Grand Total (₹1,105) | J3: High | K3: Positive | L3: System | M3: PASS
A4: 2 | B4: TC-PRC-002 | C4: Pricing, Charges, Invoice & Settlement | D4: Odd-Hour Charges | E4: Odd-hour surcharge applied for a late-night order | F4: Odd-hour charge configured by admin (e.g., 10 PM - 6 AM) | G4: 1. Place an order at 11 PM (within odd-hour window, if allowed) 2. Check invoice for surcharge | H4: Odd-hour surcharge = ₹15 | I4: Surcharge correctly added to invoice as a separate line item | J4: Medium | K4: Positive | L4: System | M4: PASS
A5: 3 | B5: TC-PRC-003 | C5: Pricing, Charges, Invoice & Settlement | D5: Weather Surcharge | E5: Bad-weather surcharge applied when configured | F5: Admin has enabled a weather surcharge for the region | G5: 1. Enable weather surcharge in admin panel 2. Place an order 3. Check invoice | H5: Weather surcharge = ₹10 | I5: Surcharge reflected correctly in the invoice and included in customer payment | J5: Medium | K5: Positive | L5: System | M5: PASS
A6: 4 | B6: TC-PRC-004 | C6: Pricing, Charges, Invoice & Settlement | D6: Packaging Charges | E6: Packaging charge varies correctly by product category | F6: Category-based packaging charge configured (e.g., sweet boxes cost more to pack) | G6: 1. Order a standard item and a sweet-box item 2. Compare packaging charges on invoice | H6: Standard packaging ₹5; Sweet-box packaging ₹20 | I6: Each item's packaging charge matches its category-specific configured rate | J6: Medium | K6: Positive | L6: System | M6: PASS
A7: 5 | B7: TC-PRC-005 | C7: Pricing, Charges, Invoice & Settlement | D7: Platform Fee | E7: Platform fee applied conditionally per configuration | F7: Admin has configured platform fee to apply above/below a threshold | G7: 1. Place an order below threshold 2. Place an order above threshold 3. Compare invoices | H7: Threshold = ₹200; Fee = ₹10 if order < ₹200 | I7: Platform fee applied only when the condition is met, per configured rule | J7: Medium | K7: Positive | L7: System | M7: FAIL
A8: 6 | B8: TC-PRC-006 | C8: Pricing, Charges, Invoice & Settlement | D8: GST Invoice | E8: GST invoice auto-generated for customer and seller | F8: Order completed successfully | G8: 1. Complete an order 2. Check customer app and seller portal for GST invoice | H8: GST-applicable order | I8: GST invoice generated and downloadable/viewable by both customer and seller with correct tax breakup | J8: High | K8: Positive | L8: System | M8: PASS
A9: 7 | B9: TC-PRC-007 | C9: Pricing, Charges, Invoice & Settlement | D9: Seller Settlement | E9: Settlement calculated after deducting commission, GST, and refunds | F9: Order delivered; commission and GST applicable; no disputes | G9: 1. Complete order lifecycle to 'Delivered' 2. Check seller settlement entry | H9: Order ₹1,000; commission 10%; GST already included | I9: Settlement shows ₹900 payable to seller (after ₹100 commission deduction), correctly itemized | J9: High | K9: Positive | L9: System | M9: FAIL
A10: 8 | B10: TC-PRC-008 | C10: Pricing, Charges, Invoice & Settlement | D10: Settlement Hold | E10: Settlement is held due to an open complaint/dispute | F10: Delivered order has an active customer complaint | G10: 1. Customer raises complaint within 24-hr window 2. Check settlement status for that order | H10: Open complaint on delivered order | I10: Settlement status shows 'On Hold' until dispute is resolved | J10: High | K10: Edge | L10: System | M10: PASS
A11: 9 | B11: TC-PRC-009 | C11: Pricing, Charges, Invoice & Settlement | D11: Settlement Release | E11: Settlement released after dispute is resolved | F11: Previously held settlement; dispute now resolved by Super Admin | G11: 1. Super Admin resolves the complaint 2. Check settlement status | H11: Resolved dispute, no refund due | I11: Settlement moves from 'On Hold' to 'Settled'/'Processing' as applicable | J11: Medium | K11: Positive | L11: System | M11: PASS
A12: 10 | B12: TC-PRC-010 | C12: Pricing, Charges, Invoice & Settlement | D12: Bulk Order Settlement | E12: Bulk order settlement calculated with its own commission rule | F12: Bulk-order-specific commission/margin rule configured | G12: 1. Place a bulk order 2. Complete delivery 3. Check settlement breakdown | H12: Bulk order value ₹50,000; bulk commission rate 6% (vs standard 10%) | I12: Settlement applies the bulk-specific commission rate, shown distinctly in admin's settlement breakdown | J12: Medium | K12: Positive | L12: System | M12: PASS
A13: 11 | B13: TC-PRC-011 | C13: Pricing, Charges, Invoice & Settlement | D13: Price Revision | E13: Price increase - customer must pay difference before processing continues | F13: Seller has revised the bill upward (e.g., due to replacement) | G13: 1. Seller sends revised bill 2. Customer notified 3. Customer pays the difference | H13: Difference amount = ₹40 | I13: Order proceeds only after additional payment is confirmed; status reflects 'Awaiting Additional Payment' until then | J13: High | K13: Positive | L13: System | M13: PASS
A14: 12 | B14: TC-PRC-012 | C14: Pricing, Charges, Invoice & Settlement | D14: Price Revision | E14: Price decrease - wallet credited automatically | F14: Seller has revised the bill downward | G14: 1. Seller sends revised (lower) bill 2. System processes automatically | H14: Difference amount = ₹25 | I14: ₹25 automatically credited to customer wallet without requiring customer action | J14: Medium | K14: Positive | L14: System | M14: FAIL
... A16: 14 | B16: TC-PRC-014 | C16: Pricing, Charges, Invoice & Settlement | D16: Wallet Shortfall | E16: Wallet balance insufficient to cover a price difference | F16: Wallet balance less than the amount due after a price increase | G16: 1. Trigger a price increase scenario 2. Attempt payment using wallet only | H16: Wallet balance ₹20; amount due ₹60 | I16: System blocks wallet-only payment and prompts for a supplementary payment method to cover the shortfall | J16: High | K16: Edge | L16: System | M16: PASS

Sheet Logistics & Delivery
A1: Logistics & Delivery Management — Test Case Scenarios
A2: S.No | B2: Test Case ID | C2: Module | D2: Sub-Feature / Flow | E2: Test Scenario | F2: Preconditions | G2: Test Steps | H2: Test Data | I2: Expected Result | J2: Priority | K2: Type | L2: Actor / Role | M2: Status
A3: 1 | B3: TC-LOG-001 | C3: Logistics & Delivery Management | D3: Self Pickup | E3: Seller enables Self Pickup only | F3: Seller configures shop delivery policy | G3: 1. Seller turns ON Self Pickup, turns OFF Self/Platform Delivery 2. Customer views shop | H3: Shop policy: Pickup=ON, Others=OFF | I3: Customer sees only 'Customer Pickup' as a fulfillment option at checkout | J3: High | K3: Positive | L3: Seller | M3: PASS
A4: 2 | B4: TC-LOG-002 | C4: Logistics & Delivery Management | D4: Self Delivery | E4: Order delivered using seller's own delivery resources | F4: Self (Seller) Delivery enabled for shop | G4: 1. Customer selects Self Delivery at checkout 2. Seller accepts and dispatches own rider | H4: Self Delivery = ON | I4: Order delivered by seller's own resources; customer pays delivery charge as configured by seller | J4: High | K4: Positive | L4: Seller | M4: FAIL
A5: 3 | B5: TC-LOG-003 | C5: Logistics & Delivery Management | D5: Platform Logistics | E5: Super Admin enables Platform Logistics on behalf of seller | F5: Seller has requested Platform Logistics | G5: 1. Super Admin opens seller's logistics config 2. Enables Platform Logistics, sets service area/charges | H5: Seller shop requesting platform logistics | I5: Platform Logistics becomes available as a fulfillment option for that shop's customers | J5: High | K5: Positive | L5: Super Admin | M5: PASS
A6: 4 | B6: TC-LOG-004 | C6: Logistics & Delivery Management | D6: Platform Logistics | E6: Delivery partner assigned only after seller accepts order | F6: Customer selected Platform Logistics; order pending seller acceptance | G6: 1. Customer places order with Platform Logistics 2. Seller accepts order 3. Observe delivery partner assignment | H6: Platform Logistics enabled | I6: Delivery partner is assigned only after seller acceptance, not before; customer address shared only post-acceptance | J6: High | K6: Positive | L6: Platform/Seller | M6: PASS
A7: 5 | B7: TC-LOG-005 | C7: Logistics & Delivery Management | D7: No Option Available | E7: All logistics options disabled or unavailable | F7: Shop has Pickup, Self Delivery, and Platform Logistics all OFF/unavailable | G7: 1. Customer attempts to place order for that shop | H7: All fulfillment options disabled | I7: System shows 'No Option Available'; order cannot be delivered; customer notified accordingly | J7: High | K7: Negative | L7: System | M7: PASS
A8: 6 | B8: TC-LOG-006 | C8: Logistics & Delivery Management | D8: No Option Available | E8: Customer address is outside the configured delivery radius | F8: Shop delivery radius configured; customer address outside range | G8: 1. Customer attempts checkout from an out-of-radius address | H8: Delivery radius = 5 km; customer at 8 km | I8: Delivery marked unavailable for that address; customer informed order cannot be delivered | J8: High | K8: Edge | L8: System | M8: PASS
A9: 7 | B9: TC-LOG-007 | C9: Logistics & Delivery Management | D9: Pickup Verification | E9: Customer pickup verified via OTP | F9: Order marked 'Ready for Pickup' | G9: 1. Customer arrives at shop 2. Provides OTP to seller 3. Seller verifies | H9: Valid pickup OTP | I9: Pickup verified and order marked 'Delivered/Completed' | J9: Medium | K9: Positive | L9: Seller/Customer | M9: PASS
A10: 8 | B10: TC-LOG-008 | C10: Logistics & Delivery Management | D10: Pickup Verification | E10: Customer pickup verified via QR Code | F10: Order marked 'Ready for Pickup' | G10: 1. Customer shows QR code 2. Seller scans code to verify | H10: Valid pickup QR | I10: Pickup verified successfully; order completed | J10: Medium | K10: Positive | L10: Seller/Customer | M10: PASS
A11: 9 | B11: TC-LOG-009 | C11: Logistics & Delivery Management | D11: Pickup Verification | E11: Invalid OTP entered during pickup verification | F11: Order marked 'Ready for Pickup' | G11: 1. Customer/representative enters an incorrect OTP | H11: Invalid OTP | I11: Verification fails; pickup not marked complete; retry allowed within attempt limit | J11: High | K11: Negative | L11: Seller | M11: FAIL
A12: 10 | B12: TC-LOG-010 | C12: Logistics & Delivery Management | D12: Dynamic Delivery Control | E12: Seller enables Vacation Mode | F12: Shop currently active | G12: 1. Seller toggles 'Vacation Mode' ON with date range | H12: Vacation Mode: 5 days | I12: Shop marked temporarily closed; no new orders accepted during this period; existing orders unaffected per rules | J12: High | K12: Positive | L12: Seller | M12: PASS
A13: 11 | B13: TC-LOG-011 | C13: Logistics & Delivery Management | D13: Dynamic Delivery Control | E13: Vacation Mode ends and previous settings auto-restore | F13: Vacation Mode active and end date reached | G13: 1. Wait/simulate Vacation Mode end date 2. Observe shop status | H13: Vacation Mode end date = today | I13: Shop automatically reopens with previous delivery policy settings restored | J13: Medium | K13: Positive | L13: System | M13: FAIL
A14: 12 | B14: TC-LOG-012 | C14: Logistics & Delivery Management | D14: Dynamic Delivery Control | E14: Auto-switch to Platform Logistics when seller is unavailable | F14: Seller Self Delivery unavailable; Auto-Switch enabled | G14: 1. Seller marked unavailable (e.g., no riders) 2. System checks auto-switch setting | H14: Auto-Switch = ON | I14: Order automatically routed to Platform Logistics without manual seller intervention | J14: Medium | K14: Positive | L14: System | M14: PASS
... A19: 17 | B19: TC-LOG-017 | C19: Logistics & Delivery Management | D19: Multi-Shop Logistics | E19: Seller manages independent delivery policies across multiple shops | F19: Seller owns 2+ shops with differing delivery configurations | G19: 1. Configure Shop 1 = Self Delivery only 2. Configure Shop 2 = Platform Logistics only 3. Place test orders on each | H19: Shop 1 & Shop 2 with different policies | I19: Each shop's orders follow its own independently configured logistics policy without cross-effect | J19: Medium | K19: Positive | L19: Seller | M19: PASS

Sheet Reward Engine
A1: Reward Engine (Cashback/Rewards/Coupons/Referral) — Test Case Scenarios
A2: S.No | B2: Test Case ID | C2: Module | D2: Sub-Feature / Flow | E2: Test Scenario | F2: Preconditions | G2: Test Steps | H2: Test Data | I2: Expected Result | J2: Priority | K2: Type | L2: Actor / Role | M2: Status
A3: 1 | B3: TC-RWD-001 | C3: Reward Engine (Cashback/Rewards/Coupons/Referral) | D3: Cashback | E3: Cashback credited to wallet after successful order completion | F3: Active cashback campaign eligible for the order | G3: 1. Place and complete an eligible order 2. Check wallet balance post-delivery | H3: 10% instant cashback campaign; order ₹500 | I3: ₹50 cashback credited to customer's wallet automatically after order completion | J3: High | K3: Positive | L3: System | M3: PASS
A4: 2 | B4: TC-RWD-002 | C4: Reward Engine (Cashback/Rewards/Coupons/Referral) | D4: Cashback | E4: Cashback reversed on order cancellation | F4: Cashback already credited for an order that is now cancelled | G4: 1. Complete order and receive cashback 2. Cancel/refund the order | H4: Cashback ₹50 credited, then order cancelled | I4: Cashback amount is reversed/debited from wallet per campaign reversal rules | J4: High | K4: Edge | L4: System | M4: PASS
A5: 3 | B5: TC-RWD-003 | C5: Reward Engine (Cashback/Rewards/Coupons/Referral) | D5: Cashback | E5: First-purchase cashback applied only once per customer | F5: Customer eligible for first-purchase cashback campaign | G5: 1. Place first order, receive cashback 2. Place a second order | H5: First-purchase cashback = ₹30 | I5: Cashback applied only on the first qualifying order; not repeated on subsequent orders | J5: Medium | K5: Positive | L5: System | M5: PASS
A6: 4 | B6: TC-RWD-004 | C6: Reward Engine (Cashback/Rewards/Coupons/Referral) | D6: Cashback | E6: Festival cashback campaign active only within scheduled dates | F6: Festival campaign configured with a start/end date | G6: 1. Place order within campaign window 2. Place order outside campaign window | H6: Campaign window: 1-3 Oct | I6: Cashback applied only for orders placed within the configured date range | J6: Medium | K6: Positive | L6: System | M6: PASS
A7: 5 | B7: TC-RWD-005 | C7: Reward Engine (Cashback/Rewards/Coupons/Referral) | D7: Coupons | E7: Coupon applied successfully when minimum purchase is met | F7: Coupon with minimum purchase validation configured | G7: 1. Add items worth ≥ minimum threshold to cart 2. Apply coupon at checkout | H7: Coupon: FLAT100, min purchase ₹500; cart ₹600 | I7: Coupon applied successfully; ₹100 discount reflected in final bill | J7: High | K7: Positive | L7: Customer | M7: PASS
A8: 6 | B8: TC-RWD-006 | C8: Reward Engine (Cashback/Rewards/Coupons/Referral) | D8: Coupons | E8: Coupon rejected when minimum purchase is not met | F8: Same coupon; cart below minimum threshold | G8: 1. Add items worth < minimum threshold 2. Attempt to apply coupon | H8: Cart ₹300 (below ₹500 minimum) | I8: Coupon application fails; system shows minimum-purchase-not-met message | J8: Medium | K8: Negative | L8: Customer | M8: PASS
A9: 7 | B9: TC-RWD-007 | C9: Reward Engine (Cashback/Rewards/Coupons/Referral) | D9: Coupons | E9: Coupon usage limit exceeded | F9: Coupon configured with a maximum usage count per customer | G9: 1. Use coupon up to its allowed limit 2. Attempt to use it again | H9: Coupon usage limit = 1 per customer | I9: Further application of the coupon is blocked with a usage-limit message | J9: Medium | K9: Negative | L9: Customer | M9: PASS
A10: 8 | B10: TC-RWD-008 | C10: Reward Engine (Cashback/Rewards/Coupons/Referral) | D10: Coupons | E10: Expired coupon rejected at checkout | F10: Coupon validity period has passed | G10: 1. Attempt to apply an expired coupon code at checkout | H10: Coupon expired yesterday | I10: Coupon rejected with an 'expired' message; no discount applied | J10: High | K10: Negative | L10: Customer | M10: PASS
A11: 9 | B11: TC-RWD-009 | C11: Reward Engine (Cashback/Rewards/Coupons/Referral) | D11: Referral | E11: Both referrer and referee rewarded after referee's first purchase | F11: Customer A refers Customer B via link/code; B registers and places first order | G11: 1. B registers using A's referral code 2. B places and completes first order | H11: Referral reward: ₹50 each | I11: Both A (referrer) and B (referee) receive ₹50 reward credited to their respective wallets | J11: High | K11: Positive | L11: System | M11: PASS
A12: 10 | B12: TC-RWD-010 | C12: Reward Engine (Cashback/Rewards/Coupons/Referral) | D12: Referral | E12: Duplicate referral attempt is blocked | F12: Referral already used once for a given referee account/device | G12: 1. Attempt to register the same referee again with a referral code, or reuse from a duplicate account | H12: Same referee/device attempting re-referral | I12: System blocks/flags duplicate referral; no additional reward issued | J12: High | K12: Negative | L12: System | M12: PASS
A13: 11 | B13: TC-RWD-011 | C13: Reward Engine (Cashback/Rewards/Coupons/Referral) | D13: Rewards Expiry | E13: Expired reward voucher is not usable | F13: Reward voucher past its validity/expiry date | G13: 1. Attempt to redeem an expired reward voucher at checkout | H13: Reward expired 2 days ago | I13: Redemption blocked; voucher shown as 'Expired' in Reward Center | J13: Medium | K13: Negative | L13: Customer | M13: PASS
A14: 12 | B14: TC-RWD-012 | C14: Reward Engine (Cashback/Rewards/Coupons/Referral) | D14: Funding Source | E14: Seller-sponsored cashback is deducted from seller settlement, not platform | F14: Cashback campaign configured as Seller Funded | G14: 1. Customer receives cashback from a seller-funded campaign 2. Check seller settlement impact | H14: Seller-funded cashback = ₹40 | I14: ₹40 deducted from seller's settlement amount; platform funding unaffected | J14: High | K14: Positive | L14: System | M14: PASS
... A18: 16 | B18: TC-RWD-016 | C18: Reward Engine (Cashback/Rewards/Coupons/Referral) | D18: Customer Reward Center | E18: Customer views cashback/reward/coupon history | F18: Customer has prior reward transactions | G18: 1. Open 'Reward Center' 2. Check My Cashback, My Rewards, My Coupons, My Referrals tabs | H18: Mixed history of cashback, coupons, referrals | I18: All historical and active reward data displayed accurately, categorized correctly | J18: Low | K18: Positive | L18: Customer | M18: PASS

Sheet Catalog, Search & Discovery
A1: Catalog, Search & Discovery — Test Case Scenarios
A2: S.No | B2: Test Case ID | C2: Module | D2: Sub-Feature / Flow | E2: Test Scenario | F2: Preconditions | G2: Test Steps | H2: Test Data | I2: Expected Result | J2: Priority | K2: Type | L2: Actor / Role | M2: Status
A3: 1 | B3: TC-CAT-001 | C3: Catalog, Search & Discovery | D3: Text Search | E3: Text search returns relevant products and stores | F3: Products/stores indexed in search system | G3: 1. Enter a keyword in search bar 2. Review results | H3: Search term: 'tomato' | I3: Relevant products and stores containing 'tomato' are returned, ranked by relevance | J3: Medium | K3: Positive | L3: Customer | M3: PASS
A4: 2 | B4: TC-CAT-002 | C4: Catalog, Search & Discovery | D4: Voice Search | E4: Voice search converts speech to text and returns results | F4: Microphone access granted | G4: 1. Tap voice search icon 2. Speak a product name 3. Review results | H4: Spoken query: 'milk' | I4: Speech accurately converted to text; relevant results for 'milk' displayed | J4: Medium | K4: Positive | L4: Customer | M4: PASS
A5: 3 | B5: TC-CAT-003 | C5: Catalog, Search & Discovery | D5: Category Search | E5: Search by category using grid-based browsing | F5: Categories/subcategories configured | G5: 1. Open 'Shop by Category' 2. Select a category tile 3. Drill into subcategory | H5: Category: Dairy & Eggs | I5: Correct subcategories and products under Dairy & Eggs are displayed | J5: Medium | K5: Positive | L5: Customer | M5: PASS
A6: 4 | B6: TC-CAT-004 | C6: Catalog, Search & Discovery | D6: Map Search | E6: Search store via map | F6: Store geolocation data available | G6: 1. Open map-based store discovery 2. Pan/zoom to locate nearby stores | H6: Customer location + nearby stores | I6: Stores are pinned accurately on the map based on their registered location | J6: Low | K6: Positive | L6: Customer | M6: PASS
A7: 5 | B7: TC-CAT-005 | C7: Catalog, Search & Discovery | D7: Stock Visibility | E7: Out-of-stock product excluded from search/browse results | F7: Product stock = 0 | G7: 1. Search for the out-of-stock product by name | H7: Product with 0 stock | I7: Product does not appear in search or category listing, per platform rule | J7: High | K7: Positive | L7: System | M7: PASS
